2023-10-02 13:04:58,897 - request_logging_helper - ERROR - sync_bot - handle_error - ID: 543a9fc44e - App Exception Thrown !/n {'response': None}
2023-10-02 13:04:58,898 - request_logging_helper - ERROR - sync_bot - handle_error - ID: 543a9fc44e - Exception Detail
Traceback (most recent call last):
  File "/home/ruban_siva/.local/lib/python3.9/site-packages/flask/app.py", line 1516, in full_dispatch_request
    rv = self.dispatch_request()
  File "/home/ruban_siva/.local/lib/python3.9/site-packages/flask/app.py", line 1492, in dispatch_request
    self.raise_routing_exception(req)
  File "/home/ruban_siva/.local/lib/python3.9/site-packages/flask/app.py", line 1474, in raise_routing_exception
    raise request.routing_exception  # type: ignore
  File "/home/ruban_siva/.local/lib/python3.9/site-packages/flask/ctx.py", line 367, in match_request
    result = self.url_adapter.match(return_rule=True)  # type: ignore
  File "/home/ruban_siva/.local/lib/python3.9/site-packages/werkzeug/routing/map.py", line 624, in match
    raise NotFound() from None
werkzeug.exceptions.NotFound: 404 Not Found: The requested URL was not found on the server. If you entered the URL manually please check your spelling and try again.
2023-10-02 13:05:09,015 - request_logging_helper - WARNING - prisma_helper - init - ID: b4f26fe803 - base_url not set!
2023-10-02 13:05:16,221 - request_logging_helper - WARNING - prisma_helper - init - ID: 46368ba362 - base_url not set!
